Traceback (most recent call last):
  File "/home/jjmachan/.pyenv/versions/3.10.12/envs/notes/lib/python3.10/site-packages/jupyter_cache/executors/utils.py", line 58, in single_nb_execution
    executenb(
  File "/home/jjmachan/.pyenv/versions/3.10.12/envs/notes/lib/python3.10/site-packages/nbclient/client.py", line 1305, in execute
    return NotebookClient(nb=nb, resources=resources, km=km, **kwargs).execute()
  File "/home/jjmachan/.pyenv/versions/3.10.12/envs/notes/lib/python3.10/site-packages/jupyter_core/utils/__init__.py", line 166, in wrapped
    return loop.run_until_complete(inner)
  File "/home/jjmachan/.pyenv/versions/3.10.12/lib/python3.10/asyncio/base_events.py", line 649, in run_until_complete
    return future.result()
  File "/home/jjmachan/.pyenv/versions/3.10.12/envs/notes/lib/python3.10/site-packages/nbclient/client.py", line 705, in async_execute
    await self.async_execute_cell(
  File "/home/jjmachan/.pyenv/versions/3.10.12/envs/notes/lib/python3.10/site-packages/nbclient/client.py", line 1058, in async_execute_cell
    await self._check_raise_for_error(cell, cell_index, exec_reply)
  File "/home/jjmachan/.pyenv/versions/3.10.12/envs/notes/lib/python3.10/site-packages/nbclient/client.py", line 914, in _check_raise_for_error
    raise CellExecutionError.from_cell_and_msg(cell, exec_reply_content)
nbclient.exceptions.CellExecutionError: An error occurred while executing the following cell:
------------------
program = guidence(
"""\
evaluate the following question and answer

 
"""
)
------------------


[0;31m---------------------------------------------------------------------------[0m
[0;31mNameError[0m                                 Traceback (most recent call last)
Cell [0;32mIn[2], line 1[0m
[0;32m----> 1[0m program [38;5;241m=[39m [43mguidence[49m(
[1;32m      2[0m [38;5;124;03m"""\[39;00m
[1;32m      3[0m [38;5;124;03mevaluate the following question and answer[39;00m
[1;32m      4[0m 
[1;32m      5[0m [38;5;124;03m [39;00m
[1;32m      6[0m [38;5;124;03m"""[39;00m
[1;32m      7[0m )

[0;31mNameError[0m: name 'guidence' is not defined

